terminate called after throwing an instance of 'vn::unknown_error'
  what():  std::exception
